# 异常处理

Rust中的错误处理方式

- 显示的`panic`主要用于测试，以及处理不可恢复的错误。
- Option 类型是为了值是可选的、或者缺少值并不是错误的情况。比如说寻找 父目录时，`/` 和 `C:` 这样的目录就没有父目录，这应当并不是一个错误。当处理 `Option` 时，`unwrap` 可用于原型开发，也可以用于能够确定 `Option` 中一定有值 的情形。然而 `expect` 更有用，因为它允许你指定一条错误信息，以免万一还是出现 了错误。
- 当错误有可能发生，且应当由调用者处理时，使用 `Result`，也可以是`unwrap`，然后使用`expect`

## panic!

会打印一个错误消息，开始回退（unwind）任务，且通常会退出程序。这里显式地在错误条件下调用 `panic`

```rust
if a>b{
	panic!("failed");
}
```

## Option和unwrap

Option：

- Some(T):找到一个属于`T`类型的元素
- None： 找不到相应元素

Option是Rust的系统类型，用来表示值不存在的问题，强制Rust检测和处理值不存在的情况。使用模式匹配来处理返回值，调用者必须处理结果为None的情况。

其中的`Option<T>`可以通过`match`显示的处理，或者使用`unwrap`隐式处理(要么返回Some内部元素，要么返回panic)

```rust
impl<T>Option<T>{
	fn unwrap(self)->T{
		match self{
            Option::Some(val)=>val,
            Option::None=> 
                  panic!("called Option::unwrap() on a None value")
        }	
	}
}
```

**unwrap遇到None是会panic**。



注： 手动使用expect方法自定义`panic`，但相比显式处理，`unwrap`的输出不太尽意。

```rust
fn f1(a:Option<&str>){
	match a{
		Some("a")=>println!("a"),
		None=>println!("None"),
	}
}
```

这方法例子Rust 有趣的介绍

```rust
fn f2(b:Option<&str>){
	let instide=b.unwrap();
    if instide=="b"{panic!("this is b but expect a");}
}
```

### unwrap_for

```rust
fn unwrap_or<T>(option: Option<T>, default: T) -> T {
    match option {
        None => default,
        Some(value) => value,
    }
```

unwrap_for 提供了一个默认值default，当值为None时返回default

### and_then

```rust
fn and_then<F, T, A>(option: Option<T>, f: F) -> Option<A>
        where F: FnOnce(T) -> Option<A> {
    match option {
        None => None,
        Some(value) => f(value),
    }
}
```

`and_then`和`map`差不多，不过`map`只是把值为`Some(T)`重新映射了一遍，`and_then`则会返回另一个`Option`。

## 组合算子：

### map

以模块化的风格来管理控制流。

Option有一个内置方法`map()`,这个组合算子用于`Some->Some`和`None->None`这类简单的映射。多个不同的`map()`,调用可以串起来。

`map()` 以链式调用的方式来简化 `match` 语句。

```rust
#![derive(dead_code)]

#[derive(Debug)] enum Food{Apple,Carrot,Potato}

#[derive(Debug)] struct Peeled(Food);
#[derive(Debug)] struct Chopped(Food);
#[derive(Debug)] struct Cooked(Food);

fn f1(food:Option<Food>)-> Option<Peeled>{
    match food{
        Some(food)=>Some(Peeled(food)),
        None => None,
    }
}

fn f2(peeled:Option<Peeled>)->Option<Choop>{
    match peeled{
		Some(Peeled<food>)=>Some(Choop(food)),
        None  =>None,
    }
}
fn f3(chopped:Option<Chopped>)->Option<Cooked>{
    chopped.map(|Chopped(food)|Cooked(food))
}


fn f4(food:Option<Food>)->Option<Cooked>{
    food.map(|f|Peeled(f))
        .map(|Peeled(f)|Chopped(f))
        .map(|Chopped(f)|Cooked(f))
}

fn f5(food:Option<Cooked>){
    match food{
        Some(food)=>println!("{:?}",num),
        None       => println!("None"),
    }
}

fn main{
    let apple=Some(Food::Apple);
    let carrot = Some(Food::Carrot);
    let potato = None;
    
    let cooked_apple=f1(f2(f3(apple)));
    let cooked_carrot=f1(f2(f3(carrot)));
    
    let cooked_potato=process(potato);
    f5(cooked_apple);
    f5(cooked_carrot);
    f5(cooked_potato);
}
```

### and_then

`and_then()` 使用被 `Option` **包裹的值来调用其输入函数并返回结果**。 如果 `Option` 是 `None`，那么它返回 `None`。

```rust
#![allow(dead_code)]

#[derive(Debug)]enum Food{CordonBleu,Steak,Sushi}
#[derive(Debug)]enum Day{Monday,Tuesday,Wednesday}

fn f1(food:Food)->Option<Food>{
    match food{
        Food::Sushi=>None,
        _ =>Some(Food),
    }
}

fn f2(food:Food)->Option<Food>{
    match food{
        Food:CordonBleu=>None,
        _=>  Some(food),
    }
}


fn f3(food:Food)->Option<Food>{
    match f2(food){
        None=>None,
        Some(food)=>match f2(food){
            None =>None,
            Some(food)=>Some(food),
        }
    }
}


fn f4(food:Food)->Option<Food>{
    f1(food).and_then(f2)
}

fn f5(food:Food,day:Day){
    match f4(food){
        Some(food) =>println!("Yay! On {:?} we get to eat {:?}.", day, food),
        None =>None,
    }
}
```

## 结果Result

Result是option的加强版，**描述的是可能的错误**而不是可能的不存在。

Result<T,E>:

- Ok<T>  : 找到T元素
- Err<E>: 返回错误

`Result` 有很多类似 `Option` 的方法。例如 `unwrap()`，它要么举出元素 `T`，要么就 `panic`。

`parse`不能总把字符串解析成指定的类型，所以`parse`返回一个`Result`表示可能的失败。

在失败的情况下，`parse()` 产生一个错误，留给 `unwrap()` 来解包并产生 `panic`。另外，`panic` 会退出我们的程序，并提供一个让人很不爽的错误消息。

```rust
fn multiply(first_number_str: &str, second_number_str: &str) -> i32 {
    // 我们试着用 `unwrap()` 把数字放出来。它会咬我们一口吗？
    let first_number = first_number_str.parse::<i32>().unwrap();
    let second_number = second_number_str.parse::<i32>().unwrap();
    first_number * second_number
}
fn main() {
    let twenty = multiply("10", "2");
    println!("double is {}", twenty);
    let tt = multiply("t", "2");
    println!("double is {}", tt);
}
```



### Result中的map

```rust
use std::num::ParseIntError;
// 就像 `Option` 那样，我们可以使用 `map()` 之类的组合算子。
// 除去写法外，这个函数与上面那个完全一致，它的作用是：
// 如果值是合法的，计算其乘积，否则返回错误。
fn multiply(first_number_str: &str, second_number_str: &str) -> Result<i32, ParseIntError> {
    first_number_str.parse::<i32>().and_then(|first_number| {
        second_number_str.parse::<i32>().map(|second_number| first_number * second_number)
    })
}
fn print(result: Result<i32, ParseIntError>) {
    match result {
        Ok(n)  => println!("n is {}", n),
        Err(e) => println!("Error: {}", e),
    }
}
fn main() {
    // 这种情况下仍然会给出正确的答案。
    let twenty = multiply("10", "2");
    print(twenty);
    // 这种情况下就会提供一条更有用的错误信息。
    let tt = multiply("t", "2");
    print(tt);
}
```

map以闭包的形式出现。

### 别名

Rust允许创建别名，

`type AliasedResult<T> = Result<T, ParseIntError>;`

## 提前返回

```rust
use std::num::ParseIntError;
fn multiply(first_number_str: &str, second_number_str: &str) -> Result<i32, ParseIntError> {
    let first_number = match first_number_str.parse::<i32>() {
        Ok(first_number)  => first_number,
        Err(e) => return Err(e),
    };
    let second_number = match second_number_str.parse::<i32>() {
        Ok(second_number)  => second_number,
        Err(e) => return Err(e),
    };
    Ok(first_number * second_number)
}
fn print(result: Result<i32, ParseIntError>) {
    match result {
        Ok(n)  => println!("n is {}", n),
        Err(e) => println!("Error: {}", e),
    }
}
fn main() {
    print(multiply("10", "2"));
    print(multiply("t", "2"));
}
```

## 引入

对于Err的策略：

- panic！  尽可能避免
- 返回  ，因为 `Err` 就意味着它已经不能被处理了。

`？` 等于一个会返回`err`而不是 `panic` 的 `unwrap`。

```rust
use std::num::ParseIntError;

fn multiply(first_number_str:&str,second_number_str:&str)->Result<i32,ParseIntError>{
    let first_number=first_number_str.parse::<i32>()?;
    let second_number = second_number_str.parse::<i32>()?;
    
    OK(first_number*second_number)
}

fn print(result:Result<i32,ParseIntError>){
    match result{
        Ok(n)=>println!(" n is {}",n),
        Err=>println!("Error:{}",e),
    }
}

fn main(){
    print(multiply("10","2"));
    print(multiply("y","2"));
}
```

### try! 

在？出现之前一直使用的是try!  当遇到Err(E)时会提早返回。

```rust
use std::num::ParseIntError;
fn multiply(first_number_str: &str, second_number_str: &str) -> Result<i32, ParseIntError> {
    let first_number = try!(first_number_str.parse::<i32>());
    let second_number = try!(second_number_str.parse::<i32>());
    Ok(first_number * second_number)
}
fn print(result: Result<i32, ParseIntError>) {
    match result {
        Ok(n)  => println!("n is {}", n),
        Err(e) => println!("Error: {}", e),
    }
}
fn main() {
    print(multiply("10", "2"));
    print(multiply("t", "2"));
}
```

## 多种错误类型

```rust
fn  f1(vec:Vec<&str>)->i32{
    let first=vec.first().unwrap();
    2*first.parse<i32>().unwrap()
}

fn main() {
    let numbers = vec!["42", "93", "18"];
    let empty = vec![];
    let strings = vec!["tofu", "93", "18"];
    println!("The first doubled is {}", f1(numbers));
    println!("The first doubled is {}", f1(empty));
    // 错误1：输入 vector 为空
    println!("The first doubled is {}", f1(strings));
    // 错误2：此元素不能解析成数字
}
```

### 从Option中取出Result

处理混合错误类型的最基本的方法就是互相包含

```rust
use std::num::ParseIntError;
fn double_first(vec: Vec<&str>) -> Option<Result<i32, ParseIntError>> {
    vec.first().map(|first| {
        first.parse::<i32>().map(|n| 2 * n)
    })
}
fn main() {
    let numbers = vec!["42", "93", "18"];
    let empty = vec![];
    let strings = vec!["tofu", "93", "18"];
    println!("The first doubled is {:?}", double_first(numbers));
    println!("The first doubled is {:?}", double_first(empty));
    // Error 1: the input vector is empty
    println!("The first doubled is {:?}", double_first(strings));
    // Error 2: the element doesn't parse to a number
}
```



某些组合算子可以交换`Result`和`Option`

```rust
use std::num::ParseIntError;
fn double_first(vec: Vec<&str>) -> Result<Option<i32>, ParseIntError> {
    let opt = vec.first().map(|first| {
        first.parse::<i32>().map(|n| 2 * n)
    });
    opt.map_or(Ok(None), |r| r.map(Some))
}
fn main() {
    let numbers = vec!["42", "93", "18"];
    let empty = vec![];
    let strings = vec!["tofu", "93", "18"];
    println!("The first doubled is {:?}", double_first(numbers));
    println!("The first doubled is {:?}", double_first(empty));
    println!("The first doubled is {:?}", double_first(strings));
}
```

## 自定义错误

错误类型：

- 用一个类型代表了多种错误
- 向用户提供了清除的错误信息
- 能够容易的与其他类型比较
  - 好的例子： `Err(EmptyVec)`
  - 坏的例子:   `Err("please use a vector with at least one element",to_owned())`
- 能够容纳错误的具体信息
  - 好的例子：`Err(BadChar(C,postition))`
  - 坏的例子： `Err("+ cannot be use here",to_owned())`
- 可以与其他错误很好的整合

```rust
use std::error;
use std::fmt;
type Result<T> = std::result::Result<T, DoubleError>;
#[derive(Debug, Clone)]
// 定义错误类型，这种类型可以根据错误处理的实际情况定制。
// 可以完全自定义错误类型，也可以在类型中完全采用底层的错误实现，
// 也可以介于二者之间。
struct DoubleError;
// 错误的生成与它如何显示是完全没关系的。没有必要担心复杂的逻辑会导致混乱的显示。
//
// 注意没有储存关于错误的任何额外信息，也就是说，如果不修改错误类型定义的话，
// 就无法指明是哪个字符串解析失败了。
impl fmt::Display for DoubleError {
    fn fmt(&self, f: &mut fmt::Formatter) -> fmt::Result {
        write!(f, "invalid first item to double")
    }
}
// 为 `DoubleError` 实现 `Error` trait，这样其他错误可以包裹这个错误类型。
impl error::Error for DoubleError {
    fn source(&self) -> Option<&(dyn error::Error + 'static)> {
        // 泛型错误，没有记录其内部原因。
        None
    }
}
fn double_first(vec: Vec<&str>) -> Result<i32> {
    vec.first()
       // 把错误换成我们的新类型。
       .ok_or(DoubleError)
       .and_then(|s| {
            s.parse::<i32>()
                // 这里也换成新类型。
                .map_err(|_| DoubleError)
                .map(|i| 2 * i)
        })
}
fn print(result: Result<i32>) {
    match result {
        Ok(n)  => println!("The first doubled is {}", n),
        Err(e) => println!("Error: {}", e),
    }
}
fn main() {
    let numbers = vec!["42", "93", "18"];
    let empty = vec![];
    let strings = vec!["tofu", "93", "18"];
    print(double_first(numbers));
    print(double_first(empty));
    print(double_first(strings));
}
```

保留原始的错误信息，可以将错误Box，但是错误只能在运行时了解，编译时不能判断

```rust
use std::error;
use std::fmt;

//类型别名
type Result<T> = std::result::Result<T,Box<error::Error>>;

#[derive(Debug,Clone)]
struct EmptyVec;

impl fmt::Display for EmptyVec{
    fn fmt(&self, f:&mut fmt::Formatter)->fmt::Result{
        write!(f,"invalid first item to double");
    }
}

impl error::Error for EmptyVec{
    fn description(&self)->&str{
        "invalid first item to double"
    }
    fn cause(&self)->Option<&error::Error>{
        None  //  泛型错误，没有记录其内部原因
    }
}

fn double_first(vec::Vec<&str>)->Result<i32>{
 	   vec.first()
          .ok_or_else(||EmptyVec.into())// 装箱
    	  .and_then(|s|{
              s.parse::<i32>()
                   .map_err(|e| e.into())
                   .map(|i| 2*i)
    })
}

fn print(result:Result<i32>){
    match result{
        Ok(n)=>println!("This first double is {}",n),
        Err(e)=>println!("Error:{}",e),
    }
}

fn main(){
    let numbers=vec!["42","78","906"];
    let empty=vec![];
    let strings=vec!["ts","78","5"];
    
    print(double_first(numbers));
    print(double_first(empty));
    print(double_first(strings));
}
```

`parse` 后总是立即把错误从标准库错误 `map` 到装箱的错误。

## **?**的其他用法 

 在parse之后，直接**立即把错误从标准库错误 `map` 到crate的错误。**

```rust
.and_then(|s| s.parse::<i32>()
    .map_err(|e| e.into())
```

相对于and_then ，？比较灵活。

 `?` 是 “要么 `unwrap` 要么 `return Err(From::from(err))`”。

From::from 是不同类型间的转换工具，即，如果错误能够转换成返回类型的地方使用`？` 他就自动转换成返回类型。

```rust
use std::error;
use std::fmt;
// 为 `Box<error::Error>` 取别名。
type Result<T> = std::result::Result<T, Box<error::Error>>;
#[derive(Debug)]
struct EmptyVec;
impl fmt::Display for EmptyVec {
    fn fmt(&self, f: &mut fmt::Formatter) -> fmt::Result {
        write!(f, "invalid first item to double")
    }
}
impl error::Error for EmptyVec {
    fn description(&self) -> &str {
        "invalid first item to double"
    }
    fn cause(&self) -> Option<&error::Error> {
        // 泛型错误，没有记录内部原因。
        None
    }
}
// 这里的结构和之前一样，但是这次没有把所有的 `Results` 和 `Options` 串起来，
// 而是使用 `?` 立即得到内部值。
fn double_first(vec: Vec<&str>) -> Result<i32> {
    let first = vec.first().ok_or(EmptyVec)?;
    let parsed = first.parse::<i32>()?;
    Ok(2 * parsed)
}
fn print(result: Result<i32>) {
    match result {
        Ok(n)  => println!("The first doubled is {}", n),
        Err(e) => println!("Error: {}", e),
    }
}
fn main() {
    let numbers = vec!["42", "93", "18"];
    let empty = vec![];
    let strings = vec!["tofu", "93", "18"];
    print(double_first(numbers));
    print(double_first(empty));
    print(double_first(strings));
}
```

与 `panic` 相比，这样做的区别在于返回类型是 `Result`，因而必须在顶层 解构它们。

## 遍历Result

```rust
fn main(){
	let strings=vec!["5","3","1"];
	let possible_elem:Vec<_> =strings
	   .into_iter()
	   .map(|s| s.parse::<i32>())
	   .collect();
	println!("Result:{:?}",possible_elem);   
}
```

注：possible_elem的类型为 Result类型 写入时需要标注

### filter_map() 

filter_map 会调用一个函数，过滤掉所有None

```rust
fn main() {
    let strings = vec!["tofu", "93", "18"];
    let numbers: Vec<_> = strings
        .into_iter()
        .filter_map(|s| s.parse::<i32>().ok())
        .collect();
    println!("Results: {:?}", numbers);
}
```

> 创建一个同时过滤和映射的迭代器。闭包必须返回Option <T>。 filter_map创建一个迭代器，该迭代器在每个元素上调用此闭包。如果闭包返回Some（element），则返回该元素。如果闭包返回None，它将重试，并在下一个元素上调用闭包，看是否将返回Some。

选择filter_map的原因：

如果闭包返回Some（element），则返回该元素。换句话说，它会自动删除Option <T>层。如果map已经返回了Option <T>，并且想跳过None，那么filter_map的使用会好很多。



`Result` 实现了 `FromIter`，因此结果的向量（`Vec<Result<T, E>>`）可以被转换成 结果包裹着向量（`Result<Vec<T>, E>`）。一旦找到一个 `Result::Err` ，遍历就被终止。

```rust
fn main() {
    let strings = vec!["tofu", "93", "18"];
    let numbers: Result<Vec<_>, _> = strings
        .into_iter()
        .map(|s| s.parse::<i32>())
        .collect();
    println!("Results: {:?}", numbers);
}
```

### 使用Partion() 收集合法值与错误

```rust
fn main() {
    let strings = vec!["tofu", "93", "18"];
    let (numbers, errors): (Vec<_>, Vec<_>) = strings
        .into_iter()
        .map(|s| s.parse::<i32>())
        .partition(Result::is_ok);
    println!("Numbers: {:?}", numbers);
    println!("Errors: {:?}", errors);
}
```



取出Result中的程序

```rust
fn main() {
    let strings = vec!["tofu", "93", "18"];
    let (numbers, errors): (Vec<_>, Vec<_>) = strings
        .into_iter()
        .map(|s| s.parse::<i32>())
        .partition(Result::is_ok);
    let numbers: Vec<_> = numbers.into_iter().map(Result::unwrap).collect();
    let errors: Vec<_> = errors.into_iter().map(Result::unwrap_err).collect();
    println!("Numbers: {:?}", numbers);
    println!("Errors: {:?}", errors);
}
```